2018-07-05 10:19:56,716 INFO: Eblog startup [in /Users/jsp/Documents/dev/documents/Study/flask/eblog/app/__init__.py:28]
2018-07-05 10:22:06,024 ERROR: Exception on / [GET] [in /Users/jsp/anaconda3/envs/vopt/lib/python3.6/site-packages/flask/app.py:1761]
Traceback (most recent call last):
  File "/Users/jsp/anaconda3/envs/vopt/lib/python3.6/site-packages/flask/app.py", line 2292, in wsgi_app
    response = self.full_dispatch_request()
  File "/Users/jsp/anaconda3/envs/vopt/lib/python3.6/site-packages/flask/app.py", line 1815, in full_dispatch_request
    rv = self.handle_user_exception(e)
  File "/Users/jsp/anaconda3/envs/vopt/lib/python3.6/site-packages/flask/app.py", line 1718, in handle_user_exception
    reraise(exc_type, exc_value, tb)
  File "/Users/jsp/anaconda3/envs/vopt/lib/python3.6/site-packages/flask/_compat.py", line 35, in reraise
    raise value
  File "/Users/jsp/anaconda3/envs/vopt/lib/python3.6/site-packages/flask/app.py", line 1813, in full_dispatch_request
    rv = self.dispatch_request()
  File "/Users/jsp/anaconda3/envs/vopt/lib/python3.6/site-packages/flask/app.py", line 1799, in dispatch_request
    return self.view_functions[rule.endpoint](**req.view_args)
  File "/Users/jsp/anaconda3/envs/vopt/lib/python3.6/site-packages/flask_login/utils.py", line 261, in decorated_view
    return func(*args, **kwargs)
  File "/Users/jsp/Documents/dev/documents/Study/flask/eblog/app/routes.py", line 26, in index
    page, app.config['POST_PER_PAGE'], False)
KeyError: 'POST_PER_PAGE'
2018-07-05 10:22:10,343 ERROR: Exception on /index [GET] [in /Users/jsp/anaconda3/envs/vopt/lib/python3.6/site-packages/flask/app.py:1761]
Traceback (most recent call last):
  File "/Users/jsp/anaconda3/envs/vopt/lib/python3.6/site-packages/flask/app.py", line 2292, in wsgi_app
    response = self.full_dispatch_request()
  File "/Users/jsp/anaconda3/envs/vopt/lib/python3.6/site-packages/flask/app.py", line 1815, in full_dispatch_request
    rv = self.handle_user_exception(e)
  File "/Users/jsp/anaconda3/envs/vopt/lib/python3.6/site-packages/flask/app.py", line 1718, in handle_user_exception
    reraise(exc_type, exc_value, tb)
  File "/Users/jsp/anaconda3/envs/vopt/lib/python3.6/site-packages/flask/_compat.py", line 35, in reraise
    raise value
  File "/Users/jsp/anaconda3/envs/vopt/lib/python3.6/site-packages/flask/app.py", line 1813, in full_dispatch_request
    rv = self.dispatch_request()
  File "/Users/jsp/anaconda3/envs/vopt/lib/python3.6/site-packages/flask/app.py", line 1799, in dispatch_request
    return self.view_functions[rule.endpoint](**req.view_args)
  File "/Users/jsp/anaconda3/envs/vopt/lib/python3.6/site-packages/flask_login/utils.py", line 261, in decorated_view
    return func(*args, **kwargs)
  File "/Users/jsp/Documents/dev/documents/Study/flask/eblog/app/routes.py", line 26, in index
    page, app.config['POST_PER_PAGE'], False)
KeyError: 'POST_PER_PAGE'
2018-07-05 10:24:16,615 INFO: Eblog startup [in /Users/jsp/Documents/dev/documents/Study/flask/eblog/app/__init__.py:28]
2018-07-05 10:25:14,713 INFO: Eblog startup [in /Users/jsp/Documents/dev/documents/Study/flask/eblog/app/__init__.py:28]
2018-07-05 10:27:00,090 INFO: Eblog startup [in /Users/jsp/Documents/dev/documents/Study/flask/eblog/app/__init__.py:28]
2018-07-05 10:27:46,760 INFO: Eblog startup [in /Users/jsp/Documents/dev/documents/Study/flask/eblog/app/__init__.py:28]
2018-07-05 10:39:56,849 INFO: Eblog startup [in /Users/jsp/Documents/dev/documents/Study/flask/eblog/app/__init__.py:28]
2018-07-05 10:53:51,146 INFO: Eblog startup [in /Users/jsp/Documents/dev/documents/Study/flask/eblog/app/__init__.py:30]
2018-07-05 10:57:05,493 INFO: Eblog startup [in /Users/jsp/Documents/dev/documents/Study/flask/eblog/app/__init__.py:30]
2018-07-05 11:01:32,928 INFO: Eblog startup [in /Users/jsp/Documents/dev/documents/Study/flask/eblog/app/__init__.py:30]
2018-07-05 18:17:02,170 INFO: Eblog startup [in /Users/jsp/Documents/dev/documents/Study/flask/eblog/app/__init__.py:30]
2018-07-05 18:19:19,483 ERROR: Exception on /reset_password_request [POST] [in /Users/jsp/anaconda3/envs/vopt/lib/python3.6/site-packages/flask/app.py:1761]
Traceback (most recent call last):
  File "/Users/jsp/anaconda3/envs/vopt/lib/python3.6/site-packages/flask/app.py", line 2292, in wsgi_app
    response = self.full_dispatch_request()
  File "/Users/jsp/anaconda3/envs/vopt/lib/python3.6/site-packages/flask/app.py", line 1815, in full_dispatch_request
    rv = self.handle_user_exception(e)
  File "/Users/jsp/anaconda3/envs/vopt/lib/python3.6/site-packages/flask/app.py", line 1718, in handle_user_exception
    reraise(exc_type, exc_value, tb)
  File "/Users/jsp/anaconda3/envs/vopt/lib/python3.6/site-packages/flask/_compat.py", line 35, in reraise
    raise value
  File "/Users/jsp/anaconda3/envs/vopt/lib/python3.6/site-packages/flask/app.py", line 1813, in full_dispatch_request
    rv = self.dispatch_request()
  File "/Users/jsp/anaconda3/envs/vopt/lib/python3.6/site-packages/flask/app.py", line 1799, in dispatch_request
    return self.view_functions[rule.endpoint](**req.view_args)
  File "/Users/jsp/Documents/dev/documents/Study/flask/eblog/app/routes.py", line 162, in reset_password_request
    send_password_reset_email(user)
  File "/Users/jsp/Documents/dev/documents/Study/flask/eblog/app/email.py", line 18, in send_password_reset_email
    user=user, token=token),
  File "/Users/jsp/anaconda3/envs/vopt/lib/python3.6/site-packages/flask/templating.py", line 135, in render_template
    context, ctx.app)
  File "/Users/jsp/anaconda3/envs/vopt/lib/python3.6/site-packages/flask/templating.py", line 117, in _render
    rv = template.render(context)
  File "/Users/jsp/anaconda3/envs/vopt/lib/python3.6/site-packages/jinja2/asyncsupport.py", line 76, in render
    return original_render(self, *args, **kwargs)
  File "/Users/jsp/anaconda3/envs/vopt/lib/python3.6/site-packages/jinja2/environment.py", line 1008, in render
    return self.environment.handle_exception(exc_info, True)
  File "/Users/jsp/anaconda3/envs/vopt/lib/python3.6/site-packages/jinja2/environment.py", line 780, in handle_exception
    reraise(exc_type, exc_value, tb)
  File "/Users/jsp/anaconda3/envs/vopt/lib/python3.6/site-packages/jinja2/_compat.py", line 37, in reraise
    raise value.with_traceback(tb)
  File "/Users/jsp/Documents/dev/documents/Study/flask/eblog/app/templates/email/reset_password.txt", line 5, in top-level template code
    {{ url_for('reset_password', token=token, _external=True) }}
  File "/Users/jsp/anaconda3/envs/vopt/lib/python3.6/site-packages/flask/helpers.py", line 356, in url_for
    return appctx.app.handle_url_build_error(error, endpoint, values)
  File "/Users/jsp/anaconda3/envs/vopt/lib/python3.6/site-packages/flask/app.py", line 2061, in handle_url_build_error
    reraise(exc_type, exc_value, tb)
  File "/Users/jsp/anaconda3/envs/vopt/lib/python3.6/site-packages/flask/_compat.py", line 35, in reraise
    raise value
  File "/Users/jsp/anaconda3/envs/vopt/lib/python3.6/site-packages/flask/helpers.py", line 345, in url_for
    force_external=external)
  File "/Users/jsp/anaconda3/envs/vopt/lib/python3.6/site-packages/werkzeug/routing.py", line 1776, in build
    raise BuildError(endpoint, values, method, self)
werkzeug.routing.BuildError: Could not build url for endpoint 'reset_password' with values ['token']. Did you mean 'reset_password_request' instead?
2018-07-05 18:24:46,509 INFO: Eblog startup [in /Users/jsp/Documents/dev/documents/Study/flask/eblog/app/__init__.py:30]
